---
title: 错误处理机制
date: 2020-12-29 10:20:10
permalink: /pages/sdesdeweew
author: 
  name: jeffery
categories: 
  - javascript
tags: 
  - javascript
---

# 错误处理机制

## Error 实例对象

`JavaScript` 解析或运行时，一旦发生错误，引擎就会抛出一个错误对象。`JavaScript` 原生提供 `Error` 构造函数，所有抛出的错误都是这个构造函数的实例。

```js
var err = new Error('出错了');
err.message // "出错了"
```
抛出 `Error` 实例对象以后，整个程序就中断在发生错误的地方，不再往下执行。

`JavaScript` 语言标准只提到，`Error`实例对象必须有`message`属性，表示出错时的提示信息，没有提到其他属性。大多数 `JavaScript` 引擎，对 `Error` 实例还提供 `name` 和 `stack` 属性，分别表示错误的名称和错误的堆栈，但它们是非标准的，不是每种实现都有。

- message：错误提示信息
- name：错误名称（非标准属性）
- stack：错误的堆栈（非标准属性）

使用 `name` 和 `message` 这两个属性，可以对发生什么错误有一个大概的了解。

```js
if (error.name) {
  console.log(error.name + ': ' + error.message);
}
```

`stack` 属性用来查看错误发生时的堆栈。

```js
function throwit() {
  throw new Error('');
}

function catchit() {
  try {
    throwit();
  } catch(e) {
    console.log(e.stack); // print stack trace
  }
}

catchit()
// Error
//    at throwit (~/examples/throwcatch.js:9:11)
//    at catchit (~/examples/throwcatch.js:3:9)
//    at repl:1:5
```

上面代码中，错误堆栈的最内层是 `throwit` 函数，然后是 `catchit` 函数，最后是函数的运行环境。

## 原生错误类型

`Error` 实例对象是最一般的错误类型，在它的基础上，`JavaScript` 还定义了其他6种错误对象。也就是说，存在 `Error` 的6个派生对象。

### SyntaxError 对象

`SyntaxError` 对象是解析代码时发生的语法错误。

```js
// 变量名错误
var 1a;
// Uncaught SyntaxError: Invalid or unexpected token

// 缺少括号
console.log 'hello');
// Uncaught SyntaxError: Unexpected string
```

### ReferenceError 对象

`ReferenceError` 对象是引用一个不存在的变量时发生的错误

```js
// 使用一个不存在的变量
unknownVariable
// Uncaught ReferenceError: unknownVariable is not defined
```

另一种触发场景是，将一个值分配给无法分配的对象，比如对函数的运行结果赋值。

```js
// 等号左侧不是变量
console.log() = 1
// Uncaught ReferenceError: Invalid left-hand side in assignment
```

### RangeError 对象

`RangeError` 对象是一个值超出有效范围时发生的错误。主要有几种情况，一是数组长度为负数，二是 `Number` 对象的方法参数超出范围，以及函数堆栈超过最大值。

```js
// 数组长度不得为负数
new Array(-1)
// Uncaught RangeError: Invalid array length
```

### TypeError 对象

`TypeError` 对象是变量或参数不是预期类型时发生的错误。比如，对字符串、布尔值、数值等原始类型的值使用 `new` 命令，就会抛出这种错误，因为 `new` 命令的参数应该是一个构造函数。

```js
new 123
// Uncaught TypeError: 123 is not a constructor

var obj = {};
obj.unknownMethod()
// Uncaught TypeError: obj.unknownMethod is not a function
```

### URIError 对象

`URIError`对象是 `URI` 相关函数的参数不正确时抛出的错误，主要涉及`encodeURI()`、`decodeURI()`、`encodeURIComponent()`、`decodeURIComponent()`、`escape()`和`unescape()`这六个函数。

```js
decodeURI('%2')
// URIError: URI malformed
```

### EvalError 对象

`eval` 函数没有被正确执行时，会抛出 `EvalError` 错误。该错误类型已经不再使用了，只是为了保证与以前代码兼容，才继续保留。

## 自定义错误

除了 `JavaScript` 原生提供的七种错误对象，还可以定义自己的错误对象。

```js
function UserError(message) {
  this.message = message || '默认信息';
  this.name = 'UserError';
}

UserError.prototype = new Error();
UserError.prototype.constructor = UserError;
```

## throw 语句

`throw` 语句的作用是手动中断程序执行，抛出一个错误。

```js
var x = -1;

if (x <= 0) {
  throw new Error('x 必须为正数');
}
// Uncaught Error: x 必须为正数
```

对于 `JavaScript` 引擎来说，遇到`throw`语句，程序就中止了。引擎会接收到`throw`抛出的信息，可能是一个错误实例，也可能是其他类型的值。

## try...catch 结构

一旦发生错误，程序就中止执行了。`JavaScript` 提供了`try...catch`结构，允许对错误进行处理，选择是否往下执行。

```js
try {
  throw new Error('出错了!');
} catch (e) {
  console.log(e.name + ": " + e.message);
  console.log(e.stack);
}
// Error: 出错了!
//   at <anonymous>:3:9
//   ...
```

如果你不确定某些代码是否会报错，就可以把它们放在 `try...catch` 代码块之中，便于进一步对错误进行处理。

`catch` 代码块捕获错误之后，程序不会中断，会按照正常流程继续执行下去

```js
try {
  throw "出错了";
} catch (e) {
  console.log(111);
}
console.log(222);
// 111
// 222
```

## finally 代码块

`try...catch` 结构允许在最后添加一个 `finally` 代码块，表示不管是否出现错误，都必需在最后运行的语句。

```js
function cleansUp() {
  try {
    throw new Error('出错了……');
    console.log('此行不会执行');
  } finally {
    console.log('完成清理工作');
  }
}

cleansUp()
// 完成清理工作
// Uncaught Error: 出错了……
//    at cleansUp (<anonymous>:3:11)
//    at <anonymous>:10:1
```